Workbook

Sheet Instructions
A1: MS Excel Practical Exam
A2: Total Questions: 30
A3: Difficulty Level: Medium
A4: Syllabus: Formulas, Logical Functions, Lookups, INDEX-MATCH, Pivot Tables & Charts, Data Analysis
A5: Attempt all questions using appropriate Excel tools/functions.

Sheet Sales_Data
A1: Order_ID | B1: Region | C1: Salesperson | D1: Product | E1: Quantity | F1: Unit_Price | G1: Sales_Date | I1: Total Sales | J1: GST | K1: Final Amount Payable | L1: IF Classification For Qantity High/Low | M1: Month Name
A2: 306 | B2: South | C2: Riya | D2: Laptop | E2: 2 | F2: 45000 | G2: 45675 | I2: =E2*F2 -> 90000 | J2: =VLOOKUP(D2,Product_Master!$A$2:$C$4,3,0) -> 18 | K2: =I2+(J2%*I2) -> 106200 | L2: =IF(E2>3,"High","Low") -> Low | M2: =TEXT(G2,"mmmm") -> January
A3: 301 | B3: North | C3: Amit | D3: Laptop | E3: 2 | F3: 45000 | G3: 45662 | I3: =E3*F3 -> 90000 | J3: =VLOOKUP(D3,Product_Master!$A$2:$C$4,3,0) -> 18 | K3: =I3+(J3%*I3) -> 106200 | L3: =IF(E3>3,"High","Low") -> Low | M3: =TEXT(G3,"mmmm") -> January
A4: 302 | B4: South | C4: Riya | D4: Mobile | E4: 5 | F4: 15000 | G4: 45664 | I4: =E4*F4 -> 75000 | J4: =VLOOKUP(D4,Product_Master!$A$2:$C$4,3,0) -> 12 | K4: =I4+(J4%*I4) -> 84000 | L4: =IF(E4>3,"High","Low") -> High | M4: =TEXT(G4,"mmmm") -> January
A5: 305 | B5: North | C5: Amit | D5: Mobile | E5: 4 | F5: 15000 | G5: 45672 | I5: =E5*F5 -> 60000 | J5: =VLOOKUP(D5,Product_Master!$A$2:$C$4,3,0) -> 12 | K5: =I5+(J5%*I5) -> 67200 | L5: =IF(E5>3,"High","Low") -> High | M5: =TEXT(G5,"mmmm") -> January
A6: 303 | B6: East | C6: Kunal | D6: Tablet | E6: 3 | F6: 18000 | G6: 45667 | I6: =E6*F6 -> 54000 | J6: =VLOOKUP(D6,Product_Master!$A$2:$C$4,3,0) -> 12 | K6: =I6+(J6%*I6) -> 60480 | L6: =IF(E6>3,"High","Low") -> Low | M6: =TEXT(G6,"mmmm") -> January
A7: 304 | B7: West | C7: Neha | D7: Laptop | E7: 1 | F7: 45000 | G7: 45669 | I7: =E7*F7 -> 45000 | J7: =VLOOKUP(D7,Product_Master!$A$2:$C$4,3,0) -> 18 | K7: =I7+(J7%*I7) -> 53100 | L7: =IF(E7>3,"High","Low") -> Low | M7: =TEXT(G7,"mmmm") -> January
J8: Grand Total : | K8: =SUM(K2:K7) -> 477180
K11: Max Final Amount | L11: =MAX(K2:K7) -> 106200
K12: Min Final Amount | L12: =MIN(K2:K7) -> 53100

Sheet Product_Master
A1: Product | B1: Category | C1: GST_%
A2: Laptop | B2: Electronics | C2: 18
A3: Mobile | B3: Electronics | C3: 12
A4: Tablet | B4: Electronics | C4: 12

Sheet Student_Marks
A1: Student_ID | B1: Name | C1: Maths | D1: Statistics | E1: Excel | F1: Attendance_% | G1: Average Marks | H1: Attendance >90
A2: 1 | B2: Rahul | C2: 78 | D2: 82 | E2: 85 | F2: 92 | G2: =AVERAGE(C2,D2,E2) -> 81.666667 | H2: =IF(F2>90,TRUE(),FALSE()) -> TRUE
A3: 2 | B3: Sneha | C3: 88 | D3: 91 | E3: 90 | F3: 96 | G3: =AVERAGE(C3,D3,E3) -> 89.666667 | H3: =IF(F3>90,TRUE(),FALSE()) -> TRUE
A4: 3 | B4: Arjun | C4: 65 | D4: 70 | E4: 72 | F4: 85 | G4: =AVERAGE(C4,D4,E4) -> 69 | H4: =IF(F4>90,TRUE(),FALSE()) -> FALSE
A5: 4 | B5: Pooja | C5: 92 | D5: 89 | E5: 94 | F5: 98 | G5: =AVERAGE(C5,D5,E5) -> 91.666667 | H5: =IF(F5>90,TRUE(),FALSE()) -> TRUE
A6: 5 | B6: Vikas | C6: 55 | D6: 60 | E6: 58 | F6: 80 | G6: =AVERAGE(C6,D6,E6) -> 57.666667 | H6: =IF(F6>90,TRUE(),FALSE()) -> FALSE
F8: =COUNTIF(F2:F6,">90") -> 3

Sheet Questions
A1: 1. Calculate Total Sales for each order (Quantity × Unit_Price). | J1: 2
A2: 2. Calculate GST Amount using VLOOKUP from Product_Master. | J2: 2
A3: 3. Find Final Amount payable (Total Sales + GST). | J3: 2
A4: 4. Find Grand Total of Final Amount. | J4: 2
A5: 5. Count total number of orders using COUNTA. | J5: 2
A6: 6. Find Region-wise total sales using SUMIF. | J6: 2
A7: 7. Use IF to classify Quantity as High (>3) or Low (<=3). | J7: 2
A8: 8. Find the maximum and minimum Final Amount. | J8: 2
A9: 9. Extract month name from Sales_Date. | J9: 2
A10: 10. Sort Sales_Data by Final Amount (Descending). | J10: 2
A11: 11. Use INDEX-MATCH to fetch Product Category. | J11: 2
A12: 12. Calculate average marks of each student. | J12: 2
... A30: 30. Protect the Student_Marks sheet. | J30: 2
J32: =SUM(J1:J30) -> 60

Sheet Answers
A1: MS Excel Practical Exam - Answer Sheet
A3: Ans-1: Total Sales for each order (Quantity x Unit_Price)
B4: Order_ID | C4: Total Sales
B5: =Sales_Data!A2 -> 306 | C5: =Sales_Data!E2*Sales_Data!F2 -> 90000
B6: =Sales_Data!A3 -> 301 | C6: =Sales_Data!E3*Sales_Data!F3 -> 90000
B7: =Sales_Data!A4 -> 302 | C7: =Sales_Data!E4*Sales_Data!F4 -> 75000
B8: =Sales_Data!A5 -> 305 | C8: =Sales_Data!E5*Sales_Data!F5 -> 60000
B9: =Sales_Data!A6 -> 303 | C9: =Sales_Data!E6*Sales_Data!F6 -> 54000
B10: =Sales_Data!A7 -> 304 | C10: =Sales_Data!E7*Sales_Data!F7 -> 45000
A13: Ans-2: GST Amount using VLOOKUP from Product_Master
B14: Order_ID | C14: Product | D14: GST %
B15: =Sales_Data!A2 -> 306 | C15: =Sales_Data!D2 -> Laptop | D15: =VLOOKUP(Sales_Data!D2,Product_Master!$A$2:$C$4,3,0) -> 18
B16: =Sales_Data!A3 -> 301 | C16: =Sales_Data!D3 -> Laptop | D16: =VLOOKUP(Sales_Data!D3,Product_Master!$A$2:$C$4,3,0) -> 18
B17: =Sales_Data!A4 -> 302 | C17: =Sales_Data!D4 -> Mobile | D17: =VLOOKUP(Sales_Data!D4,Product_Master!$A$2:$C$4,3,0) -> 12
B18: =Sales_Data!A5 -> 305 | C18: =Sales_Data!D5 -> Mobile | D18: =VLOOKUP(Sales_Data!D5,Product_Master!$A$2:$C$4,3,0) -> 12
B19: =Sales_Data!A6 -> 303 | C19: =Sales_Data!D6 -> Tablet | D19: =VLOOKUP(Sales_Data!D6,Product_Master!$A$2:$C$4,3,0) -> 12
B20: =Sales_Data!A7 -> 304 | C20: =Sales_Data!D7 -> Laptop | D20: =VLOOKUP(Sales_Data!D7,Product_Master!$A$2:$C$4,3,0) -> 18
A23: Ans-3: Final Amount Payable (Total Sales + GST)
B24: Order_ID | C24: Final Amount Payable
B25: =Sales_Data!A2 -> 306 | C25: =Sales_Data!K2 -> 106200
B26: =Sales_Data!A3 -> 301 | C26: =Sales_Data!K3 -> 106200
B27: =Sales_Data!A4 -> 302 | C27: =Sales_Data!K4 -> 84000
B28: =Sales_Data!A5 -> 305 | C28: =Sales_Data!K5 -> 67200
B29: =Sales_Data!A6 -> 303 | C29: =Sales_Data!K6 -> 60480
B30: =Sales_Data!A7 -> 304 | C30: =Sales_Data!K7 -> 53100
A33: Ans-4: Grand Total of Final Amount
B34: Grand Total
B35: =SUM(Sales_Data!K2:K7) -> 477180
A38: Ans-5: Count of total orders (COUNTA)
B39: Total Orders
B40: =COUNTA(Sales_Data!A2:A7) -> 6
A43: Ans-6: Region-wise Total Sales (SUMIF)
B44: Region | C44: Total Sales
B45: North | C45: =SUMIF(Sales_Data!$B$2:$B$7,B45,Sales_Data!$I$2:$I$7) -> 150000
B46: South | C46: =SUMIF(Sales_Data!$B$2:$B$7,B46,Sales_Data!$I$2:$I$7) -> 165000
B47: East | C47: =SUMIF(Sales_Data!$B$2:$B$7,B47,Sales_Data!$I$2:$I$7) -> 54000
B48: West | C48: =SUMIF(Sales_Data!$B$2:$B$7,B48,Sales_Data!$I$2:$I$7) -> 45000
A51: Ans-7: IF Classification of Quantity (High >3, Low <=3)
B52: Order_ID | C52: Quantity | D52: Classification
B53: =Sales_Data!A2 -> 306 | C53: =Sales_Data!E2 -> 2 | D53: =Sales_Data!L2 -> Low
...
